Workbook

Sheet Summary Tables
B2: GICS Industry | C2: % of Portfolio | D2: Dollar of Portfolio | G2: Portfolio Metrics
B3: Cash and Cash Equivalents | C3: =E3 -> 0.094854576 | D3: =SUMIF('Current Holdings'!D$4:D$61,B3,'Current Holdings'!I$4:I$61) -> 155033.52 | E3: =D3/$D$15 -> 0.094854576 | G3: Beta | H3: =SLOPE('Greek Scratch Work'!K2:K23,'Greek Scratch Work'!L2:L23) -> 0.86071282
B4: Utilities | C4: =E4 -> 0.055274158 | D4: =SUMIF('Current Holdings'!D$4:D$61,B4,'Current Holdings'!I$4:I$61) -> 90341.95 | E4: =D4/$D$15 -> 0.055274158 | G4: Alpha | H4: =INTERCEPT('Greek Scratch Work'!K2:K23,'Greek Scratch Work'!L2:L23) -> 0.0025829916
B5: Consumer Discretionary | C5: =E5 -> 0.082814981 | D5: =SUMIF('Current Holdings'!D$4:D$61,B5,'Current Holdings'!I$4:I$61) -> 135355.6 | E5: =D5/$D$15 -> 0.082814981 | G5: Sharpe Ratio | H5: =((AVERAGE('Greek Scratch Work'!C:C)-'Greek Scratch Work'!L26)/(_xlfn.STDEV.P('Greek Scratch Work'!C:C))*SQRT(252)) -> 0.94169005
B6: Consumer Staples | C6: =E6 -> 0.013038204 | D6: =SUMIF('Current Holdings'!D$4:D$61,B6,'Current Holdings'!I$4:I$61) -> 21310.08 | E6: =D6/$D$15 -> 0.013038204
B7: Health Care | C7: =E7 -> 0.13728091 | D7: =SUMIF('Current Holdings'!D$4:D$61,B7,'Current Holdings'!I$4:I$61) -> 224376.56 | E7: =D7/$D$15 -> 0.13728091
B8: Financials | C8: =E8 -> 0.17256703 | D8: =SUMIF('Current Holdings'!D$4:D$61,B8,'Current Holdings'!I$4:I$61) -> 282049.38 | E8: =D8/$D$15 -> 0.17256703
B9: Information Technology | C9: =E9 -> 0.13809048 | D9: =SUMIF('Current Holdings'!D$4:D$61,B9,'Current Holdings'!I$4:I$61) -> 225699.74 | E9: =D9/$D$15 -> 0.13809048
B10: Industrials | C10: =E10 -> 0.18421997 | D10: =SUMIF('Current Holdings'!D$4:D$61,B10,'Current Holdings'!I$4:I$61) -> 301095.34 | E10: =D10/$D$15 -> 0.18421997
B11: Energy | C11: =E11 -> 0.024596531 | D11: =SUMIF('Current Holdings'!D$4:D$61,B11,'Current Holdings'!I$4:I$61) -> 40201.4 | E11: =D11/$D$15 -> 0.024596531
B12: Real Estate | C12: =E12 -> 0.0075246611 | D12: =SUMIF('Current Holdings'!D$4:D$61,B12,'Current Holdings'!I$4:I$61) -> 12298.56 | E12: =D12/$D$15 -> 0.0075246611
B13: Communication Services | C13: =E13 -> 0.041126867 | D13: =SUMIF('Current Holdings'!D$4:D$61,B13,'Current Holdings'!I$4:I$61) -> 67219.14 | E13: =D13/$D$15 -> 0.041126867
B14: Materials | C14: =E14 -> 0.048611625 | D14: =SUMIF('Current Holdings'!D$4:D$61,B14,'Current Holdings'!I$4:I$61) -> 79452.48 | E14: =D14/$D$15 -> 0.048611625
D15: =sum(D3:D14) -> 1634433.8

Sheet Current Holdings
F2: 45658
B3: Name | C3: Ticker | D3: Sector | E3: Shares Owned | F3: Price on X Date: | G3: Current Price | H3: Average Purchase Price | I3: Current Market Value | J3: % of Portfolio | K3: Day Change | L3: Trend 30d | M3: Trend 180d | N3: $ Return | O3: YTD Return | P3: % Return Since Purchase
B4: =IFERROR(__xludf.DUMMYFUNCTION("GOOGLEFINANCE(C4,B$3)"),"Adobe Inc") -> Adobe Inc | C4: ADBE | D4: Information Technology | E4: 13 | F4: =IFERROR(__xludf.DUMMYFUNCTION("INDEX(GOOGLEFINANCE(C4,""close"",F$2),2,2)"),441.0) -> 441 | G4: =IFERROR(__xludf.DUMMYFUNCTION("GOOGLEFINANCE(C4)"),255.17) -> 255.17 | H4: 667.06 | I4: =E4*G4 -> 3317.21 | J4: =I4/$I$63 -> 0.0020295775 | K4: =IFERROR(__xludf.DUMMYFUNCTION("GOOGLEFINANCE(C4,""changepct"")/100"),0.0344) -> 0.0344 | L4: =IFERROR(__xludf.DUMMYFUNCTION("SPARKLINE(GoogleFinance(C4, ""price"", TODAY()-30,TODAY()))"),"") | M4: =IFERROR(__xludf.DUMMYFUNCTION("SPARKLINE(GoogleFinance(C4, ""price"", TODAY()-180,TODAY()))"),"") | N4: =(I4)-(H4*E4) -> -5354.57 | O4: =(G4-F4)/F4 -> -0.42138322 | P4: =((G4*E4)-(H4*E4))/(H4*E4) -> -0.61747069
B5: =IFERROR(__xludf.DUMMYFUNCTION("GOOGLEFINANCE(C5,B$3)"),"Amazon.com Inc") -> Amazon.com Inc | C5: AMZN | D5: Consumer Discretionary | E5: 260 | F5: =IFERROR(__xludf.DUMMYFUNCTION("INDEX(GOOGLEFINANCE(C5,""close"",F$2),2,2)"),220.22) -> 220.22 | G5: =IFERROR(__xludf.DUMMYFUNCTION("GOOGLEFINANCE(C5)"),208.56) -> 208.56 | H5: =(45533.8-35520.26)/E5 -> 38.513615 | I5: =E5*G5 -> 54225.6 | J5: =I5/$I$63 -> 0.033176995 | K5: =IFERROR(__xludf.DUMMYFUNCTION("GOOGLEFINANCE(C5,""changepct"")/100"),0.016) -> 0.016 | L5: =IFERROR(__xludf.DUMMYFUNCTION("SPARKLINE(GoogleFinance(C5, ""price"", TODAY()-30,TODAY()))"),"") | M5: =IFERROR(__xludf.DUMMYFUNCTION("SPARKLINE(GoogleFinance(C5, ""price"", TODAY()-180,TODAY()))"),"") | N5: =(I5)-(H5*E5) -> 44212.06 | O5: =(G5-F5)/F5 -> -0.052947053 | P5: =((G5*E5)-(H5*E5))/(H5*E5) -> 4.4152278
B6: =IFERROR(__xludf.DUMMYFUNCTION("GOOGLEFINANCE(C6,B$3)"),"American Water Works Co Inc") -> American Water Works Co Inc | C6: AWK | D6: Utilities | E6: 110 | F6: =IFERROR(__xludf.DUMMYFUNCTION("INDEX(GOOGLEFINANCE(C6,""close"",F$2),2,2)"),123.86) -> 123.86 | G6: =IFERROR(__xludf.DUMMYFUNCTION("GOOGLEFINANCE(C6)"),134.08) -> 134.08 | H6: =(15543-10503.83)/E6 -> 45.810636 | I6: =E6*G6 -> 14748.8 | J6: =I6/$I$63 -> 0.009023798 | K6: =IFERROR(__xludf.DUMMYFUNCTION("GOOGLEFINANCE(C6,""changepct"")/100"),0.009000000000000001) -> 0.009 | L6: =IFERROR(__xludf.DUMMYFUNCTION("SPARKLINE(GoogleFinance(C6, ""price"", TODAY()-30,TODAY()))"),"") | M6: =IFERROR(__xludf.DUMMYFUNCTION("SPARKLINE(GoogleFinance(C6, ""price"", TODAY()-180,TODAY()))"),"") | N6: =(I6)-(H6*E6) -> 9709.63 | O6: =(G6-F6)/F6 -> 0.082512514 | P6: =((G6*E6)-(H6*E6))/(H6*E6) -> 1.9268312
B7: =IFERROR(__xludf.DUMMYFUNCTION("GOOGLEFINANCE(C7,B$3)"),"Apple Inc") -> Apple Inc | C7: AAPL | D7: Information Technology | E7: 256 | F7: =IFERROR(__xludf.DUMMYFUNCTION("INDEX(GOOGLEFINANCE(C7,""close"",F$2),2,2)"),243.85) -> 243.85 | G7: =IFERROR(__xludf.DUMMYFUNCTION("GOOGLEFINANCE(C7)"),272.14) -> 272.14 | H7: =(58388.48-52163.94)/E7 -> 24.314609 | I7: =E7*G7 -> 69667.84 | J7: =I7/$I$63 -> 0.042625062 | K7: =IFERROR(__xludf.DUMMYFUNCTION("GOOGLEFINANCE(C7,""changepct"")/100"),0.022400000000000003) -> 0.0224 | L7: =IFERROR(__xludf.DUMMYFUNCTION("SPARKLINE(GoogleFinance(C7, ""price"", TODAY()-30,TODAY()))"),"") | M7: =IFERROR(__xludf.DUMMYFUNCTION("SPARKLINE(GoogleFinance(C7, ""price"", TODAY()-180,TODAY()))"),"") | N7: =(I7)-(H7*E7) -> 63443.3 | O7: =(G7-F7)/F7 -> 0.11601394 | P7: =((G7*E7)-(H7*E7))/(H7*E7) -> 10.192448
B8: =IFERROR(__xludf.DUMMYFUNCTION("GOOGLEFINANCE(C8,B$3)"),"Applied Materials Inc") -> Applied Materials Inc | C8: AMAT | D8: Information Technology | E8: 83 | F8: =IFERROR(__xludf.DUMMYFUNCTION("INDEX(GOOGLEFINANCE(C8,""close"",F$2),2,2)"),163.87) -> 163.87 | G8: =IFERROR(__xludf.DUMMYFUNCTION("GOOGLEFINANCE(C8)"),377.93) -> 377.93 | H8: =(16094.12-6122.77)/E8 -> 120.13675 | I8: =E8*G8 -> 31368.19 | J8: =I8/$I$63 -> 0.019192084 | K8: =IFERROR(__xludf.DUMMYFUNCTION("GOOGLEFINANCE(C8,""changepct"")/100"),0.011699999999999999) -> 0.0117 | L8: =IFERROR(__xludf.DUMMYFUNCTION("SPARKLINE(GoogleFinance(C8, ""price"", TODAY()-30,TODAY()))"),"") | M8: =IFERROR(__xludf.DUMMYFUNCTION("SPARKLINE(GoogleFinance(C8, ""price"", TODAY()-180,TODAY()))"),"") | N8: =(I8)-(H8*E8) -> 21396.84 | O8: =(G8-F8)/F8 -> 1.3062794 | P8: =((G8*E8)-(H8*E8))/(H8*E8) -> 2.1458318
B9: =IFERROR(__xludf.DUMMYFUNCTION("GOOGLEFINANCE(C9,B$3)"),"Bank of New York Mellon Corp") -> Bank of New York Mellon Corp | C9: BK | D9: Financials | E9: 188 | F9: =IFERROR(__xludf.DUMMYFUNCTION("INDEX(GOOGLEFINANCE(C9,""close"",F$2),2,2)"),77.41) -> 77.41 | G9: =IFERROR(__xludf.DUMMYFUNCTION("GOOGLEFINANCE(C9)"),116.55) -> 116.55 | H9: 55.46 | I9: =E9*G9 -> 21911.4 | J9: =I9/$I$63 -> 0.013406111 | K9: =IFERROR(__xludf.DUMMYFUNCTION("GOOGLEFINANCE(C9,""changepct"")/100"),0.0087) -> 0.0087 | L9: =IFERROR(__xludf.DUMMYFUNCTION("SPARKLINE(GoogleFinance(C9, ""price"", TODAY()-30,TODAY()))"),"") | M9: =IFERROR(__xludf.DUMMYFUNCTION("SPARKLINE(GoogleFinance(C9, ""price"", TODAY()-180,TODAY()))"),"") | N9: =(I9)-(H9*E9) -> 11484.92 | O9: =(G9-F9)/F9 -> 0.50561943 | P9: =((G9*E9)-(H9*E9))/(H9*E9) -> 1.1015146
B10: =IFERROR(__xludf.DUMMYFUNCTION("GOOGLEFINANCE(C10,B$3)"),"Barclays PLC") -> Barclays PLC | C10: BCS | D10: Financials | E10: 1000 | F10: =IFERROR(__xludf.DUMMYFUNCTION("INDEX(GOOGLEFINANCE(C10,""close"",F$2),2,2)"),13.13) -> 13.13 | G10: =IFERROR(__xludf.DUMMYFUNCTION("GOOGLEFINANCE(C10)"),25.14) -> 25.14 | H10: =(12064-1185.05)/E10 -> 10.87895 | I10: =E10*G10 -> 25140 | J10: =I10/$I$63 -> 0.015381474 | K10: =IFERROR(__xludf.DUMMYFUNCTION("GOOGLEFINANCE(C10,""changepct"")/100"),0.0012) -> 0.0012 | L10: =IFERROR(__xludf.DUMMYFUNCTION("SPARKLINE(GoogleFinance(C10, ""price"", TODAY()-30,TODAY()))"),"") | M10: =IFERROR(__xludf.DUMMYFUNCTION("SPARKLINE(GoogleFinance(C10, ""price"", TODAY()-180,TODAY()))"),"") | N10: =(I10)-(H10*E10) -> 14261.05 | O10: =(G10-F10)/F10 -> 0.91469916 | P10: =((G10*E10)-(H10*E10))/(H10*E10) -> 1.3108848
B11: =IFERROR(__xludf.DUMMYFUNCTION("GOOGLEFINANCE(C11,B$3)"),"Berkshire Hathaway Inc Class B") -> Berkshire Hathaway Inc Class B | C11: BRK.B | D11: Financials | E11: 102 | F11: =IFERROR(__xludf.DUMMYFUNCTION("INDEX(GOOGLEFINANCE(C11,""close"",F$2),2,2)"),451.1) -> 451.1 | G11: =IFERROR(__xludf.DUMMYFUNCTION("GOOGLEFINANCE(C11)"),494.51) -> 494.51 | H11: =(48054.75-14754.3)/E11 -> 326.475 | I11: =E11*G11 -> 50440.02 | J11: =I11/$I$63 -> 0.030860853 | K11: =IFERROR(__xludf.DUMMYFUNCTION("GOOGLEFINANCE(C11,""changepct"")/100"),7.000000000000001E-4) -> 0.0007 | L11: =IFERROR(__xludf.DUMMYFUNCTION("SPARKLINE(GoogleFinance(C11, ""price"", TODAY()-30,TODAY()))"),"") | M11: =IFERROR(__xludf.DUMMYFUNCTION("SPARKLINE(GoogleFinance(C11, ""price"", TODAY()-180,TODAY()))"),"") | N11: =(I11)-(H11*E11) -> 17139.57 | O11: =(G11-F11)/F11 -> 0.096231434 | P11: =((G11*E11)-(H11*E11))/(H11*E11) -> 0.51469485
B12: =IFERROR(__xludf.DUMMYFUNCTION("GOOGLEFINANCE(C12,B$3)"),"BHP Group Ltd") -> BHP Group Ltd | C12: BHP | D12: Materials | E12: 200 | F12: =IFERROR(__xludf.DUMMYFUNCTION("INDEX(GOOGLEFINANCE(C12,""close"",F$2),2,2)"),49.21) -> 49.21 | G12: =IFERROR(__xludf.DUMMYFUNCTION("GOOGLEFINANCE(C12)"),79.65) -> 79.65 | H12: =(10953+1304.56)/E12 -> 61.2878 | I12: =E12*G12 -> 15930 | J12: =I12/$I$63 -> 0.0097464948 | K12: =IFERROR(__xludf.DUMMYFUNCTION("GOOGLEFINANCE(C12,""changepct"")/100"),0.021) -> 0.021 | L12: =IFERROR(__xludf.DUMMYFUNCTION("SPARKLINE(GoogleFinance(C12, ""price"", TODAY()-30,TODAY()))"),"") | M12: =IFERROR(__xludf.DUMMYFUNCTION("SPARKLINE(GoogleFinance(C12, ""price"", TODAY()-180,TODAY()))"),"") | N12: =(I12)-(H12*E12) -> 3672.44 | O12: =(G12-F12)/F12 -> 0.61857346 | P12: =((G12*E12)-(H12*E12))/(H12*E12) -> 0.29960612
B13: =IFERROR(__xludf.DUMMYFUNCTION("GOOGLEFINANCE(C13,B$3)"),"Boston Scientific Corp") -> Boston Scientific Corp | C13: BSX | D13: Health Care | E13: 146 | F13: =IFERROR(__xludf.DUMMYFUNCTION("INDEX(GOOGLEFINANCE(C13,""close"",F$2),2,2)"),89.38) -> 89.38 | G13: =IFERROR(__xludf.DUMMYFUNCTION("GOOGLEFINANCE(C13)"),75.15) -> 75.15 | H13: 102.725 | I13: =E13*G13 -> 10971.9 | J13: =I13/$I$63 -> 0.0067129671 | K13: =IFERROR(__xludf.DUMMYFUNCTION("GOOGLEFINANCE(C13,""changepct"")/100"),0.0105) -> 0.0105 | L13: =IFERROR(__xludf.DUMMYFUNCTION("SPARKLINE(GoogleFinance(C13, ""price"", TODAY()-30,TODAY()))"),"") | M13: =IFERROR(__xludf.DUMMYFUNCTION("SPARKLINE(GoogleFinance(C13, ""price"", TODAY()-180,TODAY()))"),"") | N13: =(I13)-(H13*E13) -> -4025.95 | O13: =(G13-F13)/F13 -> -0.15920788 | P13: =((G13*E13)-(H13*E13))/(H13*E13) -> -0.26843514
B14: =IFERROR(__xludf.DUMMYFUNCTION("GOOGLEFINANCE(C14,B$3)"),"Cameco Corp") -> Cameco Corp | C14: CCJ | D14: Materials | E14: 417 | F14: =IFERROR(__xludf.DUMMYFUNCTION("INDEX(GOOGLEFINANCE(C14,""close"",F$2),2,2)"),52.16) -> 52.16 | G14: =IFERROR(__xludf.DUMMYFUNCTION("GOOGLEFINANCE(C14)"),121.08) -> 121.08 | H14: 47.86 | I14: =E14*G14 -> 50490.36 | J14: =I14/$I$63 -> 0.030891653 | K14: =IFERROR(__xludf.DUMMYFUNCTION("GOOGLEFINANCE(C14,""changepct"")/100"),0.0196) -> 0.0196 | L14: =IFERROR(__xludf.DUMMYFUNCTION("SPARKLINE(GoogleFinance(C14, ""price"", TODAY()-30,TODAY()))"),"") | M14: =IFERROR(__xludf.DUMMYFUNCTION("SPARKLINE(GoogleFinance(C14, ""price"", TODAY()-180,TODAY()))"),"") | N14: =(I14)-(H14*E14) -> 30532.74 | O14: =(G14-F14)/F14 -> 1.321319 | P14: =((G14*E14)-(H14*E14))/(H14*E14) -> 1.5298788
B15: =IFERROR(__xludf.DUMMYFUNCTION("GOOGLEFINANCE(C15,B$3)"),"Carrier Global Corp") -> Carrier Global Corp | C15: CARR | D15: Industrials | E15: 80 | F15: =IFERROR(__xludf.DUMMYFUNCTION("INDEX(GOOGLEFINANCE(C15,""close"",F$2),2,2)"),68.33) -> 68.33 | G15: =IFERROR(__xludf.DUMMYFUNCTION("GOOGLEFINANCE(C15)"),63.53) -> 63.53 | H15: =(5733.6-4358.57)/E15 -> 17.187875 | I15: =E15*G15 -> 5082.4 | J15: =I15/$I$63 -> 0.0031095785 | K15: =IFERROR(__xludf.DUMMYFUNCTION("GOOGLEFINANCE(C15,""changepct"")/100"),0.0011) -> 0.0011 | L15: =IFERROR(__xludf.DUMMYFUNCTION("SPARKLINE(GoogleFinance(C15, ""price"", TODAY()-30,TODAY()))"),"") | M15: =IFERROR(__xludf.DUMMYFUNCTION("SPARKLINE(GoogleFinance(C15, ""price"", TODAY()-180,TODAY()))"),"") | N15: =(I15)-(H15*E15) -> 3707.37 | O15: =(G15-F15)/F15 -> -0.070247329 | P15: =((G15*E15)-(H15*E15))/(H15*E15) -> 2.6962103
B16: -- | D16: Cash and Cash Equivalents | E16: 1 | I16: 65366 | J16: =I16/$I$63 -> 0.039993056
B17: =IFERROR(__xludf.DUMMYFUNCTION("GOOGLEFINANCE(C17,B$3)"),"Caterpillar Inc") -> Caterpillar Inc | C17: CAT | D17: Industrials | E17: 150 | F17: =IFERROR(__xludf.DUMMYFUNCTION("INDEX(GOOGLEFINANCE(C17,""close"",F$2),2,2)"),359.77) -> 359.77 | G17: =IFERROR(__xludf.DUMMYFUNCTION("GOOGLEFINANCE(C17)"),768.23) -> 768.23 | H17: 300.31 | I17: =E17*G17 -> 115234.5 | J17: =I17/$I$63 -> 0.070504234 | K17: =IFERROR(__xludf.DUMMYFUNCTION("GOOGLEFINANCE(C17,""changepct"")/100"),0.0147) -> 0.0147 | L17: =IFERROR(__xludf.DUMMYFUNCTION("SPARKLINE(GoogleFinance(C17, ""price"", TODAY()-30,TODAY()))"),"") | M17: =IFERROR(__xludf.DUMMYFUNCTION("SPARKLINE(GoogleFinance(C17, ""price"", TODAY()-180,TODAY()))"),"") | N17: =(I17)-(H17*E17) -> 70188 | O17: =(G17-F17)/F17 -> 1.1353365 | P17: =((G17*E17)-(H17*E17))/(H17*E17) -> 1.5581233
B18: =IFERROR(__xludf.DUMMYFUNCTION("GOOGLEFINANCE(C18,B$3)"),"Check Point Software Technologies Ltd") -> Check Point Software Technologies Ltd | C18: CHKP | D18: Information Technology | E18: 120 | F18: =IFERROR(__xludf.DUMMYFUNCTION("INDEX(GOOGLEFINANCE(C18,""close"",F$2),2,2)"),184.58) -> 184.58 | G18: =IFERROR(__xludf.DUMMYFUNCTION("GOOGLEFINANCE(C18)"),152.44) -> 152.44 | H18: 158.93 | I18: =E18*G18 -> 18292.8 | J18: =I18/$I$63 -> 0.011192133 | K18: =IFERROR(__xludf.DUMMYFUNCTION("GOOGLEFINANCE(C18,""changepct"")/100"),-0.0148) -> -0.0148 | L18: =IFERROR(__xludf.DUMMYFUNCTION("SPARKLINE(GoogleFinance(C18, ""price"", TODAY()-30,TODAY()))"),"") | M18: =IFERROR(__xludf.DUMMYFUNCTION("SPARKLINE(GoogleFinance(C18, ""price"", TODAY()-180,TODAY()))"),"") | N18: =(I18)-(H18*E18) -> -778.8 | O18: =(G18-F18)/F18 -> -0.17412504 | P18: =((G18*E18)-(H18*E18))/(H18*E18) -> -0.040835588
B19: =IFERROR(__xludf.DUMMYFUNCTION("GOOGLEFINANCE(C19,B$3)"),"Chevron Corp") -> Chevron Corp | C19: CVX | D19: Energy | E19: 80 | F19: =IFERROR(__xludf.DUMMYFUNCTION("INDEX(GOOGLEFINANCE(C19,""close"",F$2),2,2)"),146.71) -> 146.71 | G19: =IFERROR(__xludf.DUMMYFUNCTION("GOOGLEFINANCE(C19)"),185.34) -> 185.34 | H19: 147.43 | I19: =E19*G19 -> 14827.2 | J19: =I19/$I$63 -> 0.0090717657 | K19: =IFERROR(__xludf.DUMMYFUNCTION("GOOGLEFINANCE(C19,""changepct"")/100"),0.0023) -> 0.0023 | L19: =IFERROR(__xludf.DUMMYFUNCTION("SPARKLINE(GoogleFinance(C19, ""price"", TODAY()-30,TODAY()))"),"") | M19: =IFERROR(__xludf.DUMMYFUNCTION("SPARKLINE(GoogleFinance(C19, ""price"", TODAY()-180,TODAY()))"),"") | N19: =(I19)-(H19*E19) -> 3032.8 | O19: =(G19-F19)/F19 -> 0.26330857 | P19: =((G19*E19)-(H19*E19))/(H19*E19) -> 0.25713898
B20: =IFERROR(__xludf.DUMMYFUNCTION("GOOGLEFINANCE(C20,B$3)"),"Cigna Group") -> Cigna Group | C20: CI | D20: Health Care | E20: 88 | F20: =IFERROR(__xludf.DUMMYFUNCTION("INDEX(GOOGLEFINANCE(C20,""close"",F$2),2,2)"),274.49) -> 274.49 | G20: =IFERROR(__xludf.DUMMYFUNCTION("GOOGLEFINANCE(C20)"),281.0) -> 281 | H20: 255.56 | I20: =E20*G20 -> 24728 | J20: =I20/$I$63 -> 0.015129399 | K20: =IFERROR(__xludf.DUMMYFUNCTION("GOOGLEFINANCE(C20,""changepct"")/100"),-0.0077) -> -0.0077 | L20: =IFERROR(__xludf.DUMMYFUNCTION("SPARKLINE(GoogleFinance(C20, ""price"", TODAY()-30,TODAY()))"),"") | M20: =IFERROR(__xludf.DUMMYFUNCTION("SPARKLINE(GoogleFinance(C20, ""price"", TODAY()-180,TODAY()))"),"") | N20: =(I20)-(H20*E20) -> 2238.72 | O20: =(G20-F20)/F20 -> 0.023716711 | P20: =((G20*E20)-(H20*E20))/(H20*E20) -> 0.099546095
B21: =IFERROR(__xludf.DUMMYFUNCTION("GOOGLEFINANCE(C21,B$3)"),"Citizens Financial Group Inc") -> Citizens Financial Group Inc | C21: CFG | D21: Financials | E21: 250 | F21: =IFERROR(__xludf.DUMMYFUNCTION("INDEX(GOOGLEFINANCE(C21,""close"",F$2),2,2)"),43.6) -> 43.6 | G21: =IFERROR(__xludf.DUMMYFUNCTION("GOOGLEFINANCE(C21)"),62.07) -> 62.07 | H21: 40.31 | I21: =E21*G21 -> 15517.5 | J21: =I21/$I$63 -> 0.0094941138 | K21: =IFERROR(__xludf.DUMMYFUNCTION("GOOGLEFINANCE(C21,""changepct"")/100"),-0.0067) -> -0.0067 | L21: =IFERROR(__xludf.DUMMYFUNCTION("SPARKLINE(GoogleFinance(C21, ""price"", TODAY()-30,TODAY()))"),"") | M21: =IFERROR(__xludf.DUMMYFUNCTION("SPARKLINE(GoogleFinance(C21, ""price"", TODAY()-180,TODAY()))"),"") | N21: =(I21)-(H21*E21) -> 5440 | O21: =(G21-F21)/F21 -> 0.42362385 | P21: =((G21*E21)-(H21*E21))/(H21*E21) -> 0.53981642
B22: =IFERROR(__xludf.DUMMYFUNCTION("GOOGLEFINANCE(C22,B$3)"),"Coca-Cola Co") -> Coca-Cola Co | C22: KO | D22: Consumer Staples | E22: 264 | F22: =IFERROR(__xludf.DUMMYFUNCTION("INDEX(GOOGLEFINANCE(C22,""close"",F$2),2,2)"),61.84) -> 61.84 | G22: =IFERROR(__xludf.DUMMYFUNCTION("GOOGLEFINANCE(C22)"),80.72) -> 80.72 | H22: 36.67 | I22: =E22*G22 -> 21310.08 | J22: =I22/$I$63 -> 0.013038204 | K22: =IFERROR(__xludf.DUMMYFUNCTION("GOOGLEFINANCE(C22,""changepct"")/100"),0.0019) -> 0.0019 | L22: =IFERROR(__xludf.DUMMYFUNCTION("SPARKLINE(GoogleFinance(C22, ""price"", TODAY()-30,TODAY()))"),"") | M22: =IFERROR(__xludf.DUMMYFUNCTION("SPARKLINE(GoogleFinance(C22, ""price"", TODAY()-180,TODAY()))"),"") | N22: =(I22)-(H22*E22) -> 11629.2 | O22: =(G22-F22)/F22 -> 0.30530401 | P22: =((G22*E22)-(H22*E22))/(H22*E22) -> 1.2012544
B23: =IFERROR(__xludf.DUMMYFUNCTION("GOOGLEFINANCE(C23,B$3)"),"Consolidated Edison Inc") -> Consolidated Edison Inc | C23: ED | D23: Utilities | E23: 161 | F23: =IFERROR(__xludf.DUMMYFUNCTION("INDEX(GOOGLEFINANCE(C23,""close"",F$2),2,2)"),89.03) -> 89.03 | G23: =IFERROR(__xludf.DUMMYFUNCTION("GOOGLEFINANCE(C23)"),111.01) -> 111.01 | H23: 87.1 | I23: =E23*G23 -> 17872.61 | J23: =I23/$I$63 -> 0.010935047 | K23: =IFERROR(__xludf.DUMMYFUNCTION("GOOGLEFINANCE(C23,""changepct"")/100"),-0.009899999999999999) -> -0.0099 | L23: =IFERROR(__xludf.DUMMYFUNCTION("SPARKLINE(GoogleFinance(C23, ""price"", TODAY()-30,TODAY()))"),"") | M23: =IFERROR(__xludf.DUMMYFUNCTION("SPARKLINE(GoogleFinance(C23, ""price"", TODAY()-180,TODAY()))"),"") | N23: =(I23)-(H23*E23) -> 3849.51 | O23: =(G23-F23)/F23 -> 0.24688307 | P23: =((G23*E23)-(H23*E23))/(H23*E23) -> 0.27451206
B24: =IFERROR(__xludf.DUMMYFUNCTION("GOOGLEFINANCE(C24,B$3)"),"Digital Realty Trust Inc") -> Digital Realty Trust Inc | C24: DLR | D24: Real Estate | E24: 69 | F24: =IFERROR(__xludf.DUMMYFUNCTION("INDEX(GOOGLEFINANCE(C24,""close"",F$2),2,2)"),177.0) -> 177 | G24: =IFERROR(__xludf.DUMMYFUNCTION("GOOGLEFINANCE(C24)"),178.24) -> 178.24 | H24: 143.79 | I24: =E24*G24 -> 12298.56 | J24: =I24/$I$63 -> 0.0075246611 | K24: =IFERROR(__xludf.DUMMYFUNCTION("GOOGLEFINANCE(C24,""changepct"")/100"),0.012199999999999999) -> 0.0122 | L24: =IFERROR(__xludf.DUMMYFUNCTION("SPARKLINE(GoogleFinance(C24, ""price"", TODAY()-30,TODAY()))"),"") | M24: =IFERROR(__xludf.DUMMYFUNCTION("SPARKLINE(GoogleFinance(C24, ""price"", TODAY()-180,TODAY()))"),"") | N24: =(I24)-(H24*E24) -> 2377.05 | O24: =(G24-F24)/F24 -> 0.0070056497 | P24: =((G24*E24)-(H24*E24))/(H24*E24) -> 0.23958551
B25: =IFERROR(__xludf.DUMMYFUNCTION("GOOGLEFINANCE(C25,B$3)"),"Domino's Pizza Inc") -> Domino's Pizza Inc | C25: DPZ | D25: Consumer Discretionary | E25: 13 | F25: =IFERROR(__xludf.DUMMYFUNCTION("INDEX(GOOGLEFINANCE(C25,""close"",F$2),2,2)"),434.93) -> 434.93 | G25: =IFERROR(__xludf.DUMMYFUNCTION("GOOGLEFINANCE(C25)"),414.2) -> 414.2 | H25: 389.85 | I25: =E25*G25 -> 5384.6 | J25: =I25/$I$63 -> 0.0032944743 | K25: =IFERROR(__xludf.DUMMYFUNCTION("GOOGLEFINANCE(C25,""changepct"")/100"),0.0346) -> 0.0346 | L25: =IFERROR(__xludf.DUMMYFUNCTION("SPARKLINE(GoogleFinance(C25, ""price"", TODAY()-30,TODAY()))"),"") | M25: =IFERROR(__xludf.DUMMYFUNCTION("SPARKLINE(GoogleFinance(C25, ""price"", TODAY()-180,TODAY()))"),"") | N25: =(I25)-(H25*E25) -> 316.55 | O25: =(G25-F25)/F25 -> -0.047662842 | P25: =((G25*E25)-(H25*E25))/(H25*E25) -> 0.06245992
B26: =IFERROR(__xludf.DUMMYFUNCTION("GOOGLEFINANCE(C26,B$3)"),"eBay Inc") -> eBay Inc | C26: EBAY | D26: Consumer Discretionary | E26: 150 | F26: =IFERROR(__xludf.DUMMYFUNCTION("INDEX(GOOGLEFINANCE(C26,""close"",F$2),2,2)"),62.27) -> 62.27 | G26: =IFERROR(__xludf.DUMMYFUNCTION("GOOGLEFINANCE(C26)"),85.3) -> 85.3 | H26: 41.07 | I26: =E26*G26 -> 12795 | J26: =I26/$I$63 -> 0.0078283993 | K26: =IFERROR(__xludf.DUMMYFUNCTION("GOOGLEFINANCE(C26,""changepct"")/100"),0.011699999999999999) -> 0.0117 | L26: =IFERROR(__xludf.DUMMYFUNCTION("SPARKLINE(GoogleFinance(C26, ""price"", TODAY()-30,TODAY()))"),"") | M26: =IFERROR(__xludf.DUMMYFUNCTION("SPARKLINE(GoogleFinance(C26, ""price"", TODAY()-180,TODAY()))"),"") | N26: =(I26)-(H26*E26) -> 6634.5 | O26: =(G26-F26)/F26 -> 0.36984101 | P26: =((G26*E26)-(H26*E26))/(H26*E26) -> 1.0769418
B27: =IFERROR(__xludf.DUMMYFUNCTION("GOOGLEFINANCE(C27,B$3)"),"Exxon Mobil Corp") -> Exxon Mobil Corp | C27: XOM | D27: Energy | E27: 170 | F27: =IFERROR(__xludf.DUMMYFUNCTION("INDEX(GOOGLEFINANCE(C27,""close"",F$2),2,2)"),107.31) -> 107.31 | G27: =IFERROR(__xludf.DUMMYFUNCTION("GOOGLEFINANCE(C27)"),149.26) -> 149.26 | H27: 102.81 | I27: =E27*G27 -> 25374.2 | J27: =I27/$I$63 -> 0.015524765 | K27: =IFERROR(__xludf.DUMMYFUNCTION("GOOGLEFINANCE(C27,""changepct"")/100"),-0.009899999999999999) -> -0.0099 | L27: =IFERROR(__xludf.DUMMYFUNCTION("SPARKLINE(GoogleFinance(C27, ""price"", TODAY()-30,TODAY()))"),"") | M27: =IFERROR(__xludf.DUMMYFUNCTION("SPARKLINE(GoogleFinance(C27, ""price"", TODAY()-180,TODAY()))"),"") | N27: =(I27)-(H27*E27) -> 7896.5 | O27: =(G27-F27)/F27 -> 0.39092349 | P27: =((G27*E27)-(H27*E27))/(H27*E27) -> 0.4518043
B28: =IFERROR(__xludf.DUMMYFUNCTION("GOOGLEFINANCE(C28,B$3)"),"FedEx Corp") -> FedEx Corp | C28: FDX | D28: Industrials | E28: 60 | F28: =IFERROR(__xludf.DUMMYFUNCTION("INDEX(GOOGLEFINANCE(C28,""close"",F$2),2,2)"),274.28) -> 274.28 | G28: =IFERROR(__xludf.DUMMYFUNCTION("GOOGLEFINANCE(C28)"),386.56) -> 386.56 | H28: 278.57 | I28: =E28*G28 -> 23193.6 | J28: =I28/$I$63 -> 0.014190603 | K28: =IFERROR(__xludf.DUMMYFUNCTION("GOOGLEFINANCE(C28,""changepct"")/100"),0.0074) -> 0.0074 | L28: =IFERROR(__xludf.DUMMYFUNCTION("SPARKLINE(GoogleFinance(C28, ""price"", TODAY()-30,TODAY()))"),"") | M28: =IFERROR(__xludf.DUMMYFUNCTION("SPARKLINE(GoogleFinance(C28, ""price"", TODAY()-180,TODAY()))"),"") | N28: =(I28)-(H28*E28) -> 6479.4 | O28: =(G28-F28)/F28 -> 0.4093627 | P28: =((G28*E28)-(H28*E28))/(H28*E28) -> 0.3876584
B29: =IFERROR(__xludf.DUMMYFUNCTION("GOOGLEFINANCE(C29,B$3)"),"Ferrari NV") -> Ferrari NV | C29: RACE | D29: Consumer Discretionary | E29: 40 | F29: =IFERROR(__xludf.DUMMYFUNCTION("INDEX(GOOGLEFINANCE(C29,""close"",F$2),2,2)"),416.42) -> 416.42 | G29: =IFERROR(__xludf.DUMMYFUNCTION("GOOGLEFINANCE(C29)"),373.92) -> 373.92 | H29: 345.92 | I29: =E29*G29 -> 14956.8 | J29: =I29/$I$63 -> 0.0091510592 | K29: =IFERROR(__xludf.DUMMYFUNCTION("GOOGLEFINANCE(C29,""changepct"")/100"),0.0432) -> 0.0432 | L29: =IFERROR(__xludf.DUMMYFUNCTION("SPARKLINE(GoogleFinance(C29, ""price"", TODAY()-30,TODAY()))"),"") | M29: =IFERROR(__xludf.DUMMYFUNCTION("SPARKLINE(GoogleFinance(C29, ""price"", TODAY()-180,TODAY()))"),"") | N29: =(I29)-(H29*E29) -> 1120 | O29: =(G29-F29)/F29 -> -0.10206042 | P29: =((G29*E29)-(H29*E29))/(H29*E29) -> 0.080943571
B30: =IFERROR(__xludf.DUMMYFUNCTION("GOOGLEFINANCE(C30,B$3)"),"General Dynamics Corp") -> General Dynamics Corp | C30: GD | D30: Industrials | E30: 45 | F30: =IFERROR(__xludf.DUMMYFUNCTION("INDEX(GOOGLEFINANCE(C30,""close"",F$2),2,2)"),261.01) -> 261.01 | G30: =IFERROR(__xludf.DUMMYFUNCTION("GOOGLEFINANCE(C30)"),351.18) -> 351.18 | H30: 226.68 | I30: =E30*G30 -> 15803.1 | J30: =I30/$I$63 -> 0.0096688532 | K30: =IFERROR(__xludf.DUMMYFUNCTION("GOOGLEFINANCE(C30,""changepct"")/100"),0.0063) -> 0.0063 | L30: =IFERROR(__xludf.DUMMYFUNCTION("SPARKLINE(GoogleFinance(C30, ""price"", TODAY()-30,TODAY()))"),"") | M30: =IFERROR(__xludf.DUMMYFUNCTION("SPARKLINE(GoogleFinance(C30, ""price"", TODAY()-180,TODAY()))"),"") | N30: =(I30)-(H30*E30) -> 5602.5 | O30: =(G30-F30)/F30 -> 0.34546569 | P30: =((G30*E30)-(H30*E30))/(H30*E30) -> 0.5492324
B31: =IFERROR(__xludf.DUMMYFUNCTION("GOOGLEFINANCE(C31,B$3)"),"Gilead Sciences Inc") -> Gilead Sciences Inc | C31: GILD | D31: Health Care | E31: 205 | F31: =IFERROR(__xludf.DUMMYFUNCTION("INDEX(GOOGLEFINANCE(C31,""close"",F$2),2,2)"),91.88) -> 91.88 | G31: =IFERROR(__xludf.DUMMYFUNCTION("GOOGLEFINANCE(C31)"),147.64) -> 147.64 | H31: 23.03 | I31: =E31*G31 -> 30266.2 | J31: =I31/$I$63 -> 0.018517851 | K31: =IFERROR(__xludf.DUMMYFUNCTION("GOOGLEFINANCE(C31,""changepct"")/100"),-0.0146) -> -0.0146 | L31: =IFERROR(__xludf.DUMMYFUNCTION("SPARKLINE(GoogleFinance(C31, ""price"", TODAY()-30,TODAY()))"),"") | M31: =IFERROR(__xludf.DUMMYFUNCTION("SPARKLINE(GoogleFinance(C31, ""price"", TODAY()-180,TODAY()))"),"") | N31: =(I31)-(H31*E31) -> 25545.05 | O31: =(G31-F31)/F31 -> 0.60687854 | P31: =((G31*E31)-(H31*E31))/(H31*E31) -> 5.4107686
B32: =IFERROR(__xludf.DUMMYFUNCTION("GOOGLEFINANCE(C32,B$3)"),"Goldman Sachs Group Inc") -> Goldman Sachs Group Inc | C32: GS | D32: Financials | E32: 60 | F32: =IFERROR(__xludf.DUMMYFUNCTION("INDEX(GOOGLEFINANCE(C32,""close"",F$2),2,2)"),574.97) -> 574.97 | G32: =IFERROR(__xludf.DUMMYFUNCTION("GOOGLEFINANCE(C32)"),902.27) -> 902.27 | H32: 195.29 | I32: =E32*G32 -> 54136.2 | J32: =I32/$I$63 -> 0.033122297 | K32: =IFERROR(__xludf.DUMMYFUNCTION("GOOGLEFINANCE(C32,""changepct"")/100"),0.011200000000000002) -> 0.0112 | L32: =IFERROR(__xludf.DUMMYFUNCTION("SPARKLINE(GoogleFinance(C32, ""price"", TODAY()-30,TODAY()))"),"") | M32: =IFERROR(__xludf.DUMMYFUNCTION("SPARKLINE(GoogleFinance(C32, ""price"", TODAY()-180,TODAY()))"),"") | N32: =(I32)-(H32*E32) -> 42418.8 | O32: =(G32-F32)/F32 -> 0.56924709 | P32: =((G32*E32)-(H32*E32))/(H32*E32) -> 3.6201546
B33: =IFERROR(__xludf.DUMMYFUNCTION("GOOGLEFINANCE(C33,B$3)"),"Home Depot Inc") -> Home Depot Inc | C33: HD | D33: Consumer Discretionary | E33: 100 | F33: =IFERROR(__xludf.DUMMYFUNCTION("INDEX(GOOGLEFINANCE(C33,""close"",F$2),2,2)"),388.46) -> 388.46 | G33: =IFERROR(__xludf.DUMMYFUNCTION("GOOGLEFINANCE(C33)"),384.48) -> 384.48 | H33: 73.51 | I33: =E33*G33 -> 38448 | J33: =I33/$I$63 -> 0.023523743 | K33: =IFERROR(__xludf.DUMMYFUNCTION("GOOGLEFINANCE(C33,""changepct"")/100"),0.0199) -> 0.0199 | L33: =IFERROR(__xludf.DUMMYFUNCTION("SPARKLINE(GoogleFinance(C33, ""price"", TODAY()-30,TODAY()))"),"") | M33: =IFERROR(__xludf.DUMMYFUNCTION("SPARKLINE(GoogleFinance(C33, ""price"", TODAY()-180,TODAY()))"),"") | N33: =(I33)-(H33*E33) -> 31097 | O33: =(G33-F33)/F33 -> -0.010245585 | P33: =((G33*E33)-(H33*E33))/(H33*E33) -> 4.2303088
B34: =IFERROR(__xludf.DUMMYFUNCTION("GOOGLEFINANCE(C34,B$3)"),"Huron Consulting Group Inc") -> Huron Consulting Group Inc | C34: HURN | D34: Industrials | E34: 175 | F34: =IFERROR(__xludf.DUMMYFUNCTION("INDEX(GOOGLEFINANCE(C34,""close"",F$2),2,2)"),123.31) -> 123.31 | G34: =IFERROR(__xludf.DUMMYFUNCTION("GOOGLEFINANCE(C34)"),126.36) -> 126.36 | H34: 67.56 | I34: =E34*G34 -> 22113 | J34: =I34/$I$63 -> 0.013529456 | K34: =IFERROR(__xludf.DUMMYFUNCTION("GOOGLEFINANCE(C34,""changepct"")/100"),-0.0063) -> -0.0063 | L34: =IFERROR(__xludf.DUMMYFUNCTION("SPARKLINE(GoogleFinance(C34, ""price"", TODAY()-30,TODAY()))"),"") | M34: =IFERROR(__xludf.DUMMYFUNCTION("SPARKLINE(GoogleFinance(C34, ""price"", TODAY()-180,TODAY()))"),"") | N34: =(I34)-(H34*E34) -> 10290 | O34: =(G34-F34)/F34 -> 0.024734409 | P34: =((G34*E34)-(H34*E34))/(H34*E34) -> 0.87033748
B35: =IFERROR(__xludf.DUMMYFUNCTION("GOOGLEFINANCE(C35,B$3)"),"Intercontinental Exchange Inc") -> Intercontinental Exchange Inc | C35: ICE | D35: Financials | E35: 130 | F35: =IFERROR(__xludf.DUMMYFUNCTION("INDEX(GOOGLEFINANCE(C35,""close"",F$2),2,2)"),149.34) -> 149.34 | G35: =IFERROR(__xludf.DUMMYFUNCTION("GOOGLEFINANCE(C35)"),155.36) -> 155.36 | H35: 91.59 | I35: =E35*G35 -> 20196.8 | J35: =I35/$I$63 -> 0.012357062 | K35: =IFERROR(__xludf.DUMMYFUNCTION("GOOGLEFINANCE(C35,""changepct"")/100"),0.008199999999999999) -> 0.0082 | L35: =IFERROR(__xludf.DUMMYFUNCTION("SPARKLINE(GoogleFinance(C35, ""price"", TODAY()-30,TODAY()))"),"") | M35: =IFERROR(__xludf.DUMMYFUNCTION("SPARKLINE(GoogleFinance(C35, ""price"", TODAY()-180,TODAY()))"),"") | N35: =(I35)-(H35*E35) -> 8290.1 | O35: =(G35-F35)/F35 -> 0.0403107 | P35: =((G35*E35)-(H35*E35))/(H35*E35) -> 0.69625505
B36: =IFERROR(__xludf.DUMMYFUNCTION("GOOGLEFINANCE(C36,B$3)"),"Intuitive Surgical Inc") -> Intuitive Surgical Inc | C36: ISRG | D36: Health Care | E36: 47 | F36: =IFERROR(__xludf.DUMMYFUNCTION("INDEX(GOOGLEFINANCE(C36,""close"",F$2),2,2)"),524.03) -> 524.03 | G36: =IFERROR(__xludf.DUMMYFUNCTION("GOOGLEFINANCE(C36)"),494.02) -> 494.02 | H36: 533.21 | I36: =E36*G36 -> 23218.94 | J36: =I36/$I$63 -> 0.014206107 | K36: =IFERROR(__xludf.DUMMYFUNCTION("GOOGLEFINANCE(C36,""changepct"")/100"),0.0039000000000000003) -> 0.0039 | L36: =IFERROR(__xludf.DUMMYFUNCTION("SPARKLINE(GoogleFinance(C36, ""price"", TODAY()-30,TODAY()))"),"") | M36: =IFERROR(__xludf.DUMMYFUNCTION("SPARKLINE(GoogleFinance(C36, ""price"", TODAY()-180,TODAY()))"),"") | N36: =(I36)-(H36*E36) -> -1841.93 | O36: =(G36-F36)/F36 -> -0.057267714 | P36: =((G36*E36)-(H36*E36))/(H36*E36) -> -0.073498246
B37: =IFERROR(__xludf.DUMMYFUNCTION("GOOGLEFINANCE(C37,B$3)"),"JPMorgan Chase & Co") -> JPMorgan Chase & Co | C37: JPM | D37: Financials | E37: 160 | F37: =IFERROR(__xludf.DUMMYFUNCTION("INDEX(GOOGLEFINANCE(C37,""close"",F$2),2,2)"),240.0) -> 240 | G37: =IFERROR(__xludf.DUMMYFUNCTION("GOOGLEFINANCE(C37)"),297.3) -> 297.3 | H37: 39.94 | I37: =E37*G37 -> 47568 | J37: =I37/$I$63 -> 0.029103657 | K37: =IFERROR(__xludf.DUMMYFUNCTION("GOOGLEFINANCE(C37,""changepct"")/100"),-0.0012) -> -0.0012 | L37: =IFERROR(__xludf.DUMMYFUNCTION("SPARKLINE(GoogleFinance(C37, ""price"", TODAY()-30,TODAY()))"),"") | M37: =IFERROR(__xludf.DUMMYFUNCTION("SPARKLINE(GoogleFinance(C37, ""price"", TODAY()-180,TODAY()))"),"") | N37: =(I37)-(H37*E37) -> 41177.6 | O37: =(G37-F37)/F37 -> 0.23875 | P37: =((G37*E37)-(H37*E37))/(H37*E37) -> 6.4436655
B38: =IFERROR(__xludf.DUMMYFUNCTION("GOOGLEFINANCE(C38,B$3)"),"Lockheed Martin Corp") -> Lockheed Martin Corp | C38: LMT | D38: Industrials | E38: 70 | F38: =IFERROR(__xludf.DUMMYFUNCTION("INDEX(GOOGLEFINANCE(C38,""close"",F$2),2,2)"),482.25) -> 482.25 | G38: =IFERROR(__xludf.DUMMYFUNCTION("GOOGLEFINANCE(C38)"),664.43) -> 664.43 | H38: 430 | I38: =E38*G38 -> 46510.1 | J38: =I38/$I$63 -> 0.0284564 | K38: =IFERROR(__xludf.DUMMYFUNCTION("GOOGLEFINANCE(C38,""changepct"")/100"),0.0058) -> 0.0058 | L38: =IFERROR(__xludf.DUMMYFUNCTION("SPARKLINE(GoogleFinance(C38, ""price"", TODAY()-30,TODAY()))"),"") | M38: =IFERROR(__xludf.DUMMYFUNCTION("SPARKLINE(GoogleFinance(C38, ""price"", TODAY()-180,TODAY()))"),"") | N38: =(I38)-(H38*E38) -> 16410.1 | O38: =(G38-F38)/F38 -> 0.37777087 | P38: =((G38*E38)-(H38*E38))/(H38*E38) -> 0.54518605
B39: =IFERROR(__xludf.DUMMYFUNCTION("GOOGLEFINANCE(C39,B$3)"),"Manulife Financial Corp") -> Manulife Financial Corp | C39: MFC | D39: Financials | E39: 854 | F39: =IFERROR(__xludf.DUMMYFUNCTION("INDEX(GOOGLEFINANCE(C39,""close"",F$2),2,2)"),30.52) -> 30.52 | G39: =IFERROR(__xludf.DUMMYFUNCTION("GOOGLEFINANCE(C39)"),35.79) -> 35.79 | H39: 20.03 | I39: =E39*G39 -> 30564.66 | J39: =I39/$I$63 -> 0.018700458 | K39: =IFERROR(__xludf.DUMMYFUNCTION("GOOGLEFINANCE(C39,""changepct"")/100"),-0.004) -> -0.004 | L39: =IFERROR(__xludf.DUMMYFUNCTION("SPARKLINE(GoogleFinance(C39, ""price"", TODAY()-30,TODAY()))"),"") | M39: =IFERROR(__xludf.DUMMYFUNCTION("SPARKLINE(GoogleFinance(C39, ""price"", TODAY()-180,TODAY()))"),"") | N39: =(I39)-(H39*E39) -> 13459.04 | O39: =(G39-F39)/F39 -> 0.17267366 | P39: =((G39*E39)-(H39*E39))/(H39*E39) -> 0.78681977
B40: =IFERROR(__xludf.DUMMYFUNCTION("GOOGLEFINANCE(C40,B$3)"),"Medtronic PLC") -> Medtronic PLC | C40: MDT | D40: Health Care | E40: 250 | F40: =IFERROR(__xludf.DUMMYFUNCTION("INDEX(GOOGLEFINANCE(C40,""close"",F$2),2,2)"),80.22) -> 80.22 | G40: =IFERROR(__xludf.DUMMYFUNCTION("GOOGLEFINANCE(C40)"),96.75) -> 96.75 | H40: 87.54 | I40: =E40*G40 -> 24187.5 | J40: =I40/$I$63 -> 0.014798703 | K40: =IFERROR(__xludf.DUMMYFUNCTION("GOOGLEFINANCE(C40,""changepct"")/100"),-0.0189) -> -0.0189 | L40: =IFERROR(__xludf.DUMMYFUNCTION("SPARKLINE(GoogleFinance(C40, ""price"", TODAY()-30,TODAY()))"),"") | M40: =IFERROR(__xludf.DUMMYFUNCTION("SPARKLINE(GoogleFinance(C40, ""price"", TODAY()-180,TODAY()))"),"") | N40: =(I40)-(H40*E40) -> 2302.5 | O40: =(G40-F40)/F40 -> 0.20605834 | P40: =((G40*E40)-(H40*E40))/(H40*E40) -> 0.10520905
B41: =IFERROR(__xludf.DUMMYFUNCTION("GOOGLEFINANCE(C41,B$3)"),"Metlife Inc") -> Metlife Inc | C41: MET | D41: Financials | E41: 220 | F41: =IFERROR(__xludf.DUMMYFUNCTION("INDEX(GOOGLEFINANCE(C41,""close"",F$2),2,2)"),81.78) -> 81.78 | G41: =IFERROR(__xludf.DUMMYFUNCTION("GOOGLEFINANCE(C41)"),75.34) -> 75.34 | H41: 46.42 | I41: =E41*G41 -> 16574.8 | J41: =I41/$I$63 -> 0.010141004 | K41: =IFERROR(__xludf.DUMMYFUNCTION("GOOGLEFINANCE(C41,""changepct"")/100"),0.0013) -> 0.0013 | L41: =IFERROR(__xludf.DUMMYFUNCTION("SPARKLINE(GoogleFinance(C41, ""price"", TODAY()-30,TODAY()))"),"") | M41: =IFERROR(__xludf.DUMMYFUNCTION("SPARKLINE(GoogleFinance(C41, ""price"", TODAY()-180,TODAY()))"),"") | N41: =(I41)-(H41*E41) -> 6362.4 | O41: =(G41-F41)/F41 -> -0.07874786 | P41: =((G41*E41)-(H41*E41))/(H41*E41) -> 0.62300732
...

Sheet PRACTICE Equity Price Data
B1: .INX | C1: .IXIC | D1: .DJI | E1: RUT | F1: ADBE | G1: AMZN | H1: AWK | I1: AAPL | J1: AMAT | K1: BK | L1: BCS | M1: BRK.B | N1: BHP | O1: BIIB | P1: CARR | Q1: CAT | R1: CCJ | S1: CHKP | T1: CVX | U1: CI | V1: CFG | W1: KO | X1: ED | Y1: DLR | Z1: DLTR | AA1: DPZ | AB1: EBAY | AC1: XOM | AD1: FDX | AE1: RACE | AF1: GD | AG1: GM | AH1: GILD | AI1: GS | AJ1: HD | AK1: HURN | AL1: ICE | AM1: ISRG | AN1: JPM | AO1: LMT | AP1: LULU | AQ1: MFC | AR1: MDT | AS1: MET | AT1: MSFT | AU1: NEE | AV1: NVDA | AW1: OTIS | AX1: ONON | AY1: PLTR | AZ1: PYPL | BA1: PFE | BB1: RTX | BC1: TMUS | BD1: TMO | BE1: TM | BF1: TMDX | BG1: UAA | BH1: UNP | BI1: UNH | BJ1: VTIP | BK1: VTRS | BL1: WM | BM1: DIS | BN1: CASH
A2: =IFERROR(__xludf.DUMMYFUNCTION("INDEX(GOOGLEFINANCE(F$1, ""price"", DATE(2024,5,13), TODAY(), ""DAILY""), ,1)"),"#REF!") -> #REF! | B2: =IFERROR(__xludf.DUMMYFUNCTION("INDEX(GOOGLEFINANCE(B$1, ""price"", DATE(2024,5,13), TODAY(), ""DAILY""), ,2)"),"Close") -> Close | C2: =IFERROR(__xludf.DUMMYFUNCTION("INDEX(GOOGLEFINANCE(C$1, ""price"", DATE(2024,5,13), TODAY(), ""DAILY""), ,2)"),"Close") -> Close | D2: =IFERROR(__xludf.DUMMYFUNCTION("INDEX(GOOGLEFINANCE(D$1, ""price"", DATE(2024,5,13), TODAY(), ""DAILY""), ,2)"),"Close") -> Close | E2: =IFERROR(__xludf.DUMMYFUNCTION("INDEX(GOOGLEFINANCE(E$1, ""price"", DATE(2024,5,13), TODAY(), ""DAILY""), ,2)"),"Close") -> Close | F2: =IFERROR(__xludf.DUMMYFUNCTION("INDEX(GOOGLEFINANCE(F$1, ""price"", DATE(2024,5,13), TODAY(), ""DAILY""), ,2)"),"Close") -> Close | G2: =IFERROR(__xludf.DUMMYFUNCTION("INDEX(GOOGLEFINANCE(G$1, ""price"", DATE(2024,5,13), TODAY(), ""DAILY""), ,2)"),"Close") -> Close | H2: =IFERROR(__xludf.DUMMYFUNCTION("INDEX(GOOGLEFINANCE(H$1, ""price"", DATE(2024,5,13), TODAY(), ""DAILY""), ,2)"),"Close") -> Close | I2: =IFERROR(__xludf.DUMMYFUNCTION("INDEX(GOOGLEFINANCE(I$1, ""price"", DATE(2024,5,13), TODAY(), ""DAILY""), ,2)"),"Close") -> Close | J2: =IFERROR(__xludf.DUMMYFUNCTION("INDEX(GOOGLEFINANCE(J$1, ""price"", DATE(2024,5,13), TODAY(), ""DAILY""), ,2)"),"Close") -> Close | K2: =IFERROR(__xludf.DUMMYFUNCTION("INDEX(GOOGLEFINANCE(K$1, ""price"", DATE(2024,5,13), TODAY(), ""DAILY""), ,2)"),"Close") -> Close | L2: =IFERROR(__xludf.DUMMYFUNCTION("INDEX(GOOGLEFINANCE(L$1, ""price"", DATE(2024,5,13), TODAY(), ""DAILY""), ,2)"),"Close") -> Close | M2: =IFERROR(__xludf.DUMMYFUNCTION("INDEX(GOOGLEFINANCE(M$1, ""price"", DATE(2024,5,13), TODAY(), ""DAILY""), ,2)"),"Close") -> Close | N2: =IFERROR(__xludf.DUMMYFUNCTION("INDEX(GOOGLEFINANCE(N$1, ""price"", DATE(2024,5,13), TODAY(), ""DAILY""), ,2)"),"Close") -> Close | O2: =IFERROR(__xludf.DUMMYFUNCTION("INDEX(GOOGLEFINANCE(O$1, ""price"", DATE(2024,5,13), TODAY(), ""DAILY""), ,2)"),"Close") -> Close | P2: =IFERROR(__xludf.DUMMYFUNCTION("INDEX(GOOGLEFINANCE(P$1, ""price"", DATE(2024,5,13), TODAY(), ""DAILY""), ,2)"),"Close") -> Close | Q2: =IFERROR(__xludf.DUMMYFUNCTION("INDEX(GOOGLEFINANCE(Q$1, ""price"", DATE(2024,5,13), TODAY(), ""DAILY""), ,2)"),"Close") -> Close | R2: =IFERROR(__xludf.DUMMYFUNCTION("INDEX(GOOGLEFINANCE(R$1, ""price"", DATE(2024,5,13), TODAY(), ""DAILY""), ,2)"),"Close") -> Close | S2: =IFERROR(__xludf.DUMMYFUNCTION("INDEX(GOOGLEFINANCE(S$1, ""price"", DATE(2024,5,13), TODAY(), ""DAILY""), ,2)"),"Close") -> Close | T2: =IFERROR(__xludf.DUMMYFUNCTION("INDEX(GOOGLEFINANCE(T$1, ""price"", DATE(2024,5,13), TODAY(), ""DAILY""), ,2)"),"Close") -> Close | U2: =IFERROR(__xludf.DUMMYFUNCTION("INDEX(GOOGLEFINANCE(U$1, ""price"", DATE(2024,5,13), TODAY(), ""DAILY""), ,2)"),"Close") -> Close | V2: =IFERROR(__xludf.DUMMYFUNCTION("INDEX(GOOGLEFINANCE(V$1, ""price"", DATE(2024,5,13), TODAY(), ""DAILY""), ,2)"),"Close") -> Close | W2: =IFERROR(__xludf.DUMMYFUNCTION("INDEX(GOOGLEFINANCE(W$1, ""price"", DATE(2024,5,13), TODAY(), ""DAILY""), ,2)"),"Close") -> Close | X2: =IFERROR(__xludf.DUMMYFUNCTION("INDEX(GOOGLEFINANCE(X$1, ""price"", DATE(2024,5,13), TODAY(), ""DAILY""), ,2)"),"Close") -> Close | Y2: =IFERROR(__xludf.DUMMYFUNCTION("INDEX(GOOGLEFINANCE(Y$1, ""price"", DATE(2024,5,13), TODAY(), ""DAILY""), ,2)"),"Close") -> Close | Z2: =IFERROR(__xludf.DUMMYFUNCTION("INDEX(GOOGLEFINANCE(Z$1, ""price"", DATE(2024,5,13), TODAY(), ""DAILY""), ,2)"),"Close") -> Close | AA2: =IFERROR(__xludf.DUMMYFUNCTION("INDEX(GOOGLEFINANCE(AA$1, ""price"", DATE(2024,5,13), TODAY(), ""DAILY""), ,2)"),"Close") -> Close | AB2: =IFERROR(__xludf.DUMMYFUNCTION("INDEX(GOOGLEFINANCE(AB$1, ""price"", DATE(2024,5,13), TODAY(), ""DAILY""), ,2)"),"Close") -> Close | AC2: =IFERROR(__xludf.DUMMYFUNCTION("INDEX(GOOGLEFINANCE(AC$1, ""price"", DATE(2024,5,13), TODAY(), ""DAILY""), ,2)"),"Close") -> Close | AD2: =IFERROR(__xludf.DUMMYFUNCTION("INDEX(GOOGLEFINANCE(AD$1, ""price"", DATE(2024,5,13), TODAY(), ""DAILY""), ,2)"),"Close") -> Close | AE2: =IFERROR(__xludf.DUMMYFUNCTION("INDEX(GOOGLEFINANCE(AE$1, ""price"", DATE(2024,5,13), TODAY(), ""DAILY""), ,2)"),"Close") -> Close | AF2: =IFERROR(__xludf.DUMMYFUNCTION("INDEX(GOOGLEFINANCE(AF$1, ""price"", DATE(2024,5,13), TODAY(), ""DAILY""), ,2)"),"Close") -> Close | AG2: =IFERROR(__xludf.DUMMYFUNCTION("INDEX(GOOGLEFINANCE(AG$1, ""price"", DATE(2024,5,13), TODAY(), ""DAILY""), ,2)"),"Close") -> Close | AH2: =IFERROR(__xludf.DUMMYFUNCTION("INDEX(GOOGLEFINANCE(AH$1, ""price"", DATE(2024,5,13), TODAY(), ""DAILY""), ,2)"),"Close") -> Close | AI2: =IFERROR(__xludf.DUMMYFUNCTION("INDEX(GOOGLEFINANCE(AI$1, ""price"", DATE(2024,5,13), TODAY(), ""DAILY""), ,2)"),"Close") -> Close | AJ2: =IFERROR(__xludf.DUMMYFUNCTION("INDEX(GOOGLEFINANCE(AJ$1, ""price"", DATE(2024,5,13), TODAY(), ""DAILY""), ,2)"),"Close") -> Close | AK2: =IFERROR(__xludf.DUMMYFUNCTION("INDEX(GOOGLEFINANCE(AK$1, ""price"", DATE(2024,5,13), TODAY(), ""DAILY""), ,2)"),"Close") -> Close | AL2: =IFERROR(__xludf.DUMMYFUNCTION("INDEX(GOOGLEFINANCE(AL$1, ""price"", DATE(2024,5,13), TODAY(), ""DAILY""), ,2)"),"Close") -> Close | AM2: =IFERROR(__xludf.DUMMYFUNCTION("INDEX(GOOGLEFINANCE(AM$1, ""price"", DATE(2024,5,13), TODAY(), ""DAILY""), ,2)"),"Close") -> Close | AN2: =IFERROR(__xludf.DUMMYFUNCTION("INDEX(GOOGLEFINANCE(AN$1, ""price"", DATE(2024,5,13), TODAY(), ""DAILY""), ,2)"),"Close") -> Close | AO2: =IFERROR(__xludf.DUMMYFUNCTION("INDEX(GOOGLEFINANCE(AO$1, ""price"", DATE(2024,5,13), TODAY(), ""DAILY""), ,2)"),"Close") -> Close | AP2: =IFERROR(__xludf.DUMMYFUNCTION("INDEX(GOOGLEFINANCE(AP$1, ""price"", DATE(2024,5,13), TODAY(), ""DAILY""), ,2)"),"Close") -> Close | AQ2: =IFERROR(__xludf.DUMMYFUNCTION("INDEX(GOOGLEFINANCE(AQ$1, ""price"", DATE(2024,5,13), TODAY(), ""DAILY""), ,2)"),"Close") -> Close | AR2: =IFERROR(__xludf.DUMMYFUNCTION("INDEX(GOOGLEFINANCE(AR$1, ""price"", DATE(2024,5,13), TODAY(), ""DAILY""), ,2)"),"Close") -> Close | AS2: =IFERROR(__xludf.DUMMYFUNCTION("INDEX(GOOGLEFINANCE(AS$1, ""price"", DATE(2024,5,13), TODAY(), ""DAILY""), ,2)"),"Close") -> Close | AT2: =IFERROR(__xludf.DUMMYFUNCTION("INDEX(GOOGLEFINANCE(AT$1, ""price"", DATE(2024,5,13), TODAY(), ""DAILY""), ,2)"),"Close") -> Close | AU2: =IFERROR(__xludf.DUMMYFUNCTION("INDEX(GOOGLEFINANCE(AU$1, ""price"", DATE(2024,5,13), TODAY(), ""DAILY""), ,2)"),"Close") -> Close | AV2: =IFERROR(__xludf.DUMMYFUNCTION("INDEX(GOOGLEFINANCE(AV$1, ""price"", DATE(2024,5,13), TODAY(), ""DAILY""), ,2)"),"Close") -> Close | AW2: =IFERROR(__xludf.DUMMYFUNCTION("INDEX(GOOGLEFINANCE(AW$1, ""price"", DATE(2024,5,13), TODAY(), ""DAILY""), ,2)"),"Close") -> Close | AX2: =IFERROR(__xludf.DUMMYFUNCTION("INDEX(GOOGLEFINANCE(AX$1, ""price"", DATE(2024,5,13), TODAY(), ""DAILY""), ,2)"),"Close") -> Close | AY2: =IFERROR(__xludf.DUMMYFUNCTION("INDEX(GOOGLEFINANCE(AY$1, ""price"", DATE(2024,5,13), TODAY(), ""DAILY""), ,2)"),"Close") -> Close | AZ2: =IFERROR(__xludf.DUMMYFUNCTION("INDEX(GOOGLEFINANCE(AZ$1, ""price"", DATE(2024,5,13), TODAY(), ""DAILY""), ,2)"),"Close") -> Close | BA2: =IFERROR(__xludf.DUMMYFUNCTION("INDEX(GOOGLEFINANCE(BA$1, ""price"", DATE(2024,5,13), TODAY(), ""DAILY""), ,2)"),"Close") -> Close | BB2: =IFERROR(__xludf.DUMMYFUNCTION("INDEX(GOOGLEFINANCE(BB$1, ""price"", DATE(2024,5,13), TODAY(), ""DAILY""), ,2)"),"Close") -> Close | BC2: =IFERROR(__xludf.DUMMYFUNCTION("INDEX(GOOGLEFINANCE(BC$1, ""price"", DATE(2024,5,13), TODAY(), ""DAILY""), ,2)"),"Close") -> Close | BD2: =IFERROR(__xludf.DUMMYFUNCTION("INDEX(GOOGLEFINANCE(BD$1, ""price"", DATE(2024,5,13), TODAY(), ""DAILY""), ,2)"),"Close") -> Close | BE2: =IFERROR(__xludf.DUMMYFUNCTION("INDEX(GOOGLEFINANCE(BE$1, ""price"", DATE(2024,5,13), TODAY(), ""DAILY""), ,2)"),"Close") -> Close | BF2: =IFERROR(__xludf.DUMMYFUNCTION("INDEX(GOOGLEFINANCE(BF$1, ""price"", DATE(2024,5,13), TODAY(), ""DAILY""), ,2)"),"Close") -> Close | BG2: =IFERROR(__xludf.DUMMYFUNCTION("INDEX(GOOGLEFINANCE(BG$1, ""price"", DATE(2024,5,13), TODAY(), ""DAILY""), ,2)"),"Close") -> Close | BH2: =IFERROR(__xludf.DUMMYFUNCTION("INDEX(GOOGLEFINANCE(BH$1, ""price"", DATE(2024,5,13), TODAY(), ""DAILY""), ,2)"),"Close") -> Close | BI2: =IFERROR(__xludf.DUMMYFUNCTION("INDEX(GOOGLEFINANCE(BI$1, ""price"", DATE(2024,5,13), TODAY(), ""DAILY""), ,2)"),"Close") -> Close | BJ2: =IFERROR(__xludf.DUMMYFUNCTION("INDEX(GOOGLEFINANCE(BJ$1, ""price"", DATE(2024,5,13), TODAY(), ""DAILY""), ,2)"),"Close") -> Close | BK2: =IFERROR(__xludf.DUMMYFUNCTION("INDEX(GOOGLEFINANCE(BK$1, ""price"", DATE(2024,5,13), TODAY(), ""DAILY""), ,2)"),"Close") -> Close | BL2: =IFERROR(__xludf.DUMMYFUNCTION("INDEX(GOOGLEFINANCE(BL$1, ""price"", DATE(2024,5,13), TODAY(), ""DAILY""), ,2)"),"Close") -> Close | BM2: =IFERROR(__xludf.DUMMYFUNCTION("INDEX(GOOGLEFINANCE(BM$1, ""price"", DATE(2024,5,13), TODAY(), ""DAILY""), ,2)"),"Close") -> Close | BN2: Close
A3: 45425.667 | B3: =IFERROR(__xludf.DUMMYFUNCTION("""COMPUTED_VALUE"""),5221.42) -> 5221.42 | C3: =IFERROR(__xludf.DUMMYFUNCTION("""COMPUTED_VALUE"""),16388.24) -> 16388.24 | D3: =IFERROR(__xludf.DUMMYFUNCTION("""COMPUTED_VALUE"""),39431.51) -> 39431.51 | E3: =IFERROR(__xludf.DUMMYFUNCTION("""COMPUTED_VALUE"""),2062.12) -> 2062.12 | F3: =IFERROR(__xludf.DUMMYFUNCTION("""COMPUTED_VALUE"""),483.11) -> 483.11 | G3: =IFERROR(__xludf.DUMMYFUNCTION("""COMPUTED_VALUE"""),186.57) -> 186.57 | H3: =IFERROR(__xludf.DUMMYFUNCTION("""COMPUTED_VALUE"""),133.78) -> 133.78 | I3: =IFERROR(__xludf.DUMMYFUNCTION("""COMPUTED_VALUE"""),186.28) -> 186.28 | J3: =IFERROR(__xludf.DUMMYFUNCTION("""COMPUTED_VALUE"""),206.63) -> 206.63 | K3: =IFERROR(__xludf.DUMMYFUNCTION("""COMPUTED_VALUE"""),57.85) -> 57.85 | L3: =IFERROR(__xludf.DUMMYFUNCTION("""COMPUTED_VALUE"""),10.84) -> 10.84 | M3: =IFERROR(__xludf.DUMMYFUNCTION("""COMPUTED_VALUE"""),411.22) -> 411.22 | N3: =IFERROR(__xludf.DUMMYFUNCTION("""COMPUTED_VALUE"""),57.18) -> 57.18 | O3: =IFERROR(__xludf.DUMMYFUNCTION("""COMPUTED_VALUE"""),225.34) -> 225.34 | P3: =IFERROR(__xludf.DUMMYFUNCTION("""COMPUTED_VALUE"""),64.33) -> 64.33 | Q3: =IFERROR(__xludf.DUMMYFUNCTION("""COMPUTED_VALUE"""),356.68) -> 356.68 | R3: =IFERROR(__xludf.DUMMYFUNCTION("""COMPUTED_VALUE"""),48.98) -> 48.98 | S3: =IFERROR(__xludf.DUMMYFUNCTION("""COMPUTED_VALUE"""),150.03) -> 150.03 | T3: =IFERROR(__xludf.DUMMYFUNCTION("""COMPUTED_VALUE"""),164.53) -> 164.53 | U3: =IFERROR(__xludf.DUMMYFUNCTION("""COMPUTED_VALUE"""),349.14) -> 349.14 | V3: =IFERROR(__xludf.DUMMYFUNCTION("""COMPUTED_VALUE"""),35.94) -> 35.94 | W3: =IFERROR(__xludf.DUMMYFUNCTION("""COMPUTED_VALUE"""),63.58) -> 63.58 | X3: =IFERROR(__xludf.DUMMYFUNCTION("""COMPUTED_VALUE"""),97.64) -> 97.64 | Y3: =IFERROR(__xludf.DUMMYFUNCTION("""COMPUTED_VALUE"""),143.09) -> 143.09 | Z3: =IFERROR(__xludf.DUMMYFUNCTION("""COMPUTED_VALUE"""),120.2) -> 120.2 | AA3: =IFERROR(__xludf.DUMMYFUNCTION("""COMPUTED_VALUE"""),510.24) -> 510.24 | AB3: =IFERROR(__xludf.DUMMYFUNCTION("""COMPUTED_VALUE"""),51.99) -> 51.99 | AC3: =IFERROR(__xludf.DUMMYFUNCTION("""COMPUTED_VALUE"""),117.91) -> 117.91 | AD3: =IFERROR(__xludf.DUMMYFUNCTION("""COMPUTED_VALUE"""),266.89) -> 266.89 | AE3: =IFERROR(__xludf.DUMMYFUNCTION("""COMPUTED_VALUE"""),405.73) -> 405.73 | AF3: =IFERROR(__xludf.DUMMYFUNCTION("""COMPUTED_VALUE"""),293.53) -> 293.53 | AG3: =IFERROR(__xludf.DUMMYFUNCTION("""COMPUTED_VALUE"""),45.17) -> 45.17 | AH3: =IFERROR(__xludf.DUMMYFUNCTION("""COMPUTED_VALUE"""),67.54) -> 67.54 | AI3: =IFERROR(__xludf.DUMMYFUNCTION("""COMPUTED_VALUE"""),453.56) -> 453.56 | AJ3: =IFERROR(__xludf.DUMMYFUNCTION("""COMPUTED_VALUE"""),340.96) -> 340.96 | AK3: =IFERROR(__xludf.DUMMYFUNCTION("""COMPUTED_VALUE"""),87.33) -> 87.33 | AL3: =IFERROR(__xludf.DUMMYFUNCTION("""COMPUTED_VALUE"""),133.74) -> 133.74 | AM3: =IFERROR(__xludf.DUMMYFUNCTION("""COMPUTED_VALUE"""),380.88) -> 380.88 | AN3: =IFERROR(__xludf.DUMMYFUNCTION("""COMPUTED_VALUE"""),198.73) -> 198.73 | AO3: =IFERROR(__xludf.DUMMYFUNCTION("""COMPUTED_VALUE"""),470.56) -> 470.56 | AP3: =IFERROR(__xludf.DUMMYFUNCTION("""COMPUTED_VALUE"""),347.16) -> 347.16 | AQ3: =IFERROR(__xludf.DUMMYFUNCTION("""COMPUTED_VALUE"""),25.69) -> 25.69 | AR3: =IFERROR(__xludf.DUMMYFUNCTION("""COMPUTED_VALUE"""),83.52) -> 83.52 | AS3: =IFERROR(__xludf.DUMMYFUNCTION("""COMPUTED_VALUE"""),72.41) -> 72.41 | AT3: =IFERROR(__xludf.DUMMYFUNCTION("""COMPUTED_VALUE"""),413.72) -> 413.72 | AU3: =IFERROR(__xludf.DUMMYFUNCTION("""COMPUTED_VALUE"""),74.58) -> 74.58 | AV3: =IFERROR(__xludf.DUMMYFUNCTION("""COMPUTED_VALUE"""),90.4) -> 90.4 | AW3: =IFERROR(__xludf.DUMMYFUNCTION("""COMPUTED_VALUE"""),96.59) -> 96.59 | AX3: =IFERROR(__xludf.DUMMYFUNCTION("""COMPUTED_VALUE"""),30.69) -> 30.69 | AY3: =IFERROR(__xludf.DUMMYFUNCTION("""COMPUTED_VALUE"""),20.94) -> 20.94 | AZ3: =IFERROR(__xludf.DUMMYFUNCTION("""COMPUTED_VALUE"""),63.95) -> 63.95 | BA3: =IFERROR(__xludf.DUMMYFUNCTION("""COMPUTED_VALUE"""),28.44) -> 28.44 | BB3: =IFERROR(__xludf.DUMMYFUNCTION("""COMPUTED_VALUE"""),105.8) -> 105.8 | BC3: =IFERROR(__xludf.DUMMYFUNCTION("""COMPUTED_VALUE"""),163.35) -> 163.35 | BD3: =IFERROR(__xludf.DUMMYFUNCTION("""COMPUTED_VALUE"""),590.7) -> 590.7 | BE3: =IFERROR(__xludf.DUMMYFUNCTION("""COMPUTED_VALUE"""),215.64) -> 215.64 | BF3: =IFERROR(__xludf.DUMMYFUNCTION("""COMPUTED_VALUE"""),132.04) -> 132.04 | BG3: =IFERROR(__xludf.DUMMYFUNCTION("""COMPUTED_VALUE"""),6.78) -> 6.78 | BH3: =IFERROR(__xludf.DUMMYFUNCTION("""COMPUTED_VALUE"""),245.68) -> 245.68 | BI3: =IFERROR(__xludf.DUMMYFUNCTION("""COMPUTED_VALUE"""),511.74) -> 511.74 | BJ3: =IFERROR(__xludf.DUMMYFUNCTION("""COMPUTED_VALUE"""),48.05) -> 48.05 | BK3: =IFERROR(__xludf.DUMMYFUNCTION("""COMPUTED_VALUE"""),11.36) -> 11.36 | BL3: =IFERROR(__xludf.DUMMYFUNCTION("""COMPUTED_VALUE"""),210.82) -> 210.82 | BM3: =IFERROR(__xludf.DUMMYFUNCTION("""COMPUTED_VALUE"""),105.83) -> 105.83
A4: 45426.667 | B4: =IFERROR(__xludf.DUMMYFUNCTION("""COMPUTED_VALUE"""),5246.68) -> 5246.68 | C4: =IFERROR(__xludf.DUMMYFUNCTION("""COMPUTED_VALUE"""),16511.18) -> 16511.18 | D4: =IFERROR(__xludf.DUMMYFUNCTION("""COMPUTED_VALUE"""),39558.11) -> 39558.11 | E4: =IFERROR(__xludf.DUMMYFUNCTION("""COMPUTED_VALUE"""),2085.69) -> 2085.69 | F4: =IFERROR(__xludf.DUMMYFUNCTION("""COMPUTED_VALUE"""),475.95) -> 475.95 | G4: =IFERROR(__xludf.DUMMYFUNCTION("""COMPUTED_VALUE"""),187.07) -> 187.07 | H4: =IFERROR(__xludf.DUMMYFUNCTION("""COMPUTED_VALUE"""),133.13) -> 133.13 | I4: =IFERROR(__xludf.DUMMYFUNCTION("""COMPUTED_VALUE"""),187.43) -> 187.43 | J4: =IFERROR(__xludf.DUMMYFUNCTION("""COMPUTED_VALUE"""),209.82) -> 209.82 | K4: =IFERROR(__xludf.DUMMYFUNCTION("""COMPUTED_VALUE"""),58.35) -> 58.35 | L4: =IFERROR(__xludf.DUMMYFUNCTION("""COMPUTED_VALUE"""),11.04) -> 11.04 | M4: =IFERROR(__xludf.DUMMYFUNCTION("""COMPUTED_VALUE"""),410.24) -> 410.24 | N4: =IFERROR(__xludf.DUMMYFUNCTION("""COMPUTED_VALUE"""),58.79) -> 58.79 | O4: =IFERROR(__xludf.DUMMYFUNCTION("""COMPUTED_VALUE"""),226.88) -> 226.88 | P4: =IFERROR(__xludf.DUMMYFUNCTION("""COMPUTED_VALUE"""),64.96) -> 64.96 | Q4: =IFERROR(__xludf.DUMMYFUNCTION("""COMPUTED_VALUE"""),358.18) -> 358.18 | R4: =IFERROR(__xludf.DUMMYFUNCTION("""COMPUTED_VALUE"""),49.98) -> 49.98 | S4: =IFERROR(__xludf.DUMMYFUNCTION("""COMPUTED_VALUE"""),148.91) -> 148.91 | T4: =IFERROR(__xludf.DUMMYFUNCTION("""COMPUTED_VALUE"""),163.61) -> 163.61 | U4: =IFERROR(__xludf.DUMMYFUNCTION("""COMPUTED_VALUE"""),346.42) -> 346.42 | V4: =IFERROR(__xludf.DUMMYFUNCTION("""COMPUTED_VALUE"""),36.43) -> 36.43 | W4: =IFERROR(__xludf.DUMMYFUNCTION("""COMPUTED_VALUE"""),63.1) -> 63.1 | X4: =IFERROR(__xludf.DUMMYFUNCTION("""COMPUTED_VALUE"""),96.64) -> 96.64 | Y4: =IFERROR(__xludf.DUMMYFUNCTION("""COMPUTED_VALUE"""),141.86) -> 141.86 | Z4: =IFERROR(__xludf.DUMMYFUNCTION("""COMPUTED_VALUE"""),118.88) -> 118.88 | AA4: =IFERROR(__xludf.DUMMYFUNCTION("""COMPUTED_VALUE"""),510.71) -> 510.71 | AB4: =IFERROR(__xludf.DUMMYFUNCTION("""COMPUTED_VALUE"""),52.1) -> 52.1 | AC4: =IFERROR(__xludf.DUMMYFUNCTION("""COMPUTED_VALUE"""),117.67) -> 117.67 | AD4: =IFERROR(__xludf.DUMMYFUNCTION("""COMPUTED_VALUE"""),259.04) -> 259.04 | AE4: =IFERROR(__xludf.DUMMYFUNCTION("""COMPUTED_VALUE"""),411.02) -> 411.02 | AF4: =IFERROR(__xludf.DUMMYFUNCTION("""COMPUTED_VALUE"""),294.06) -> 294.06 | AG4: =IFERROR(__xludf.DUMMYFUNCTION("""COMPUTED_VALUE"""),45.03) -> 45.03 | AH4: =IFERROR(__xludf.DUMMYFUNCTION("""COMPUTED_VALUE"""),67.65) -> 67.65 | AI4: =IFERROR(__xludf.DUMMYFUNCTION("""COMPUTED_VALUE"""),458.47) -> 458.47 | AJ4: =IFERROR(__xludf.DUMMYFUNCTION("""COMPUTED_VALUE"""),340.5) -> 340.5 | AK4: =IFERROR(__xludf.DUMMYFUNCTION("""COMPUTED_VALUE"""),87.12) -> 87.12 | AL4: =IFERROR(__xludf.DUMMYFUNCTION("""COMPUTED_VALUE"""),134.39) -> 134.39 | AM4: =IFERROR(__xludf.DUMMYFUNCTION("""COMPUTED_VALUE"""),384.19) -> 384.19 | AN4: =IFERROR(__xludf.DUMMYFUNCTION("""COMPUTED_VALUE"""),201.51) -> 201.51 | AO4: =IFERROR(__xludf.DUMMYFUNCTION("""COMPUTED_VALUE"""),467.18) -> 467.18 | AP4: =IFERROR(__xludf.DUMMYFUNCTION("""COMPUTED_VALUE"""),352.35) -> 352.35 | AQ4: =IFERROR(__xludf.DUMMYFUNCTION("""COMPUTED_VALUE"""),26.01) -> 26.01 | AR4: =IFERROR(__xludf.DUMMYFUNCTION("""COMPUTED_VALUE"""),84.3) -> 84.3 | AS4: =IFERROR(__xludf.DUMMYFUNCTION("""COMPUTED_VALUE"""),73.31) -> 73.31 | AT4: =IFERROR(__xludf.DUMMYFUNCTION("""COMPUTED_VALUE"""),416.56) -> 416.56 | AU4: =IFERROR(__xludf.DUMMYFUNCTION("""COMPUTED_VALUE"""),75.42) -> 75.42 | AV4: =IFERROR(__xludf.DUMMYFUNCTION("""COMPUTED_VALUE"""),91.36) -> 91.36 | AW4: =IFERROR(__xludf.DUMMYFUNCTION("""COMPUTED_VALUE"""),97.07) -> 97.07 | AX4: =IFERROR(__xludf.DUMMYFUNCTION("""COMPUTED_VALUE"""),36.3) -> 36.3 | AY4: =IFERROR(__xludf.DUMMYFUNCTION("""COMPUTED_VALUE"""),21.44) -> 21.44 | AZ4: =IFERROR(__xludf.DUMMYFUNCTION("""COMPUTED_VALUE"""),64.58) -> 64.58 | BA4: =IFERROR(__xludf.DUMMYFUNCTION("""COMPUTED_VALUE"""),28.38) -> 28.38 | BB4: =IFERROR(__xludf.DUMMYFUNCTION("""COMPUTED_VALUE"""),105.7) -> 105.7 | BC4: =IFERROR(__xludf.DUMMYFUNCTION("""COMPUTED_VALUE"""),162.41) -> 162.41 | BD4: =IFERROR(__xludf.DUMMYFUNCTION("""COMPUTED_VALUE"""),594.8) -> 594.8 | BE4: =IFERROR(__xludf.DUMMYFUNCTION("""COMPUTED_VALUE"""),217.12) -> 217.12 | BF4: =IFERROR(__xludf.DUMMYFUNCTION("""COMPUTED_VALUE"""),132.44) -> 132.44 | BG4: =IFERROR(__xludf.DUMMYFUNCTION("""COMPUTED_VALUE"""),6.83) -> 6.83 | BH4: =IFERROR(__xludf.DUMMYFUNCTION("""COMPUTED_VALUE"""),244.94) -> 244.94 | BI4: =IFERROR(__xludf.DUMMYFUNCTION("""COMPUTED_VALUE"""),513.88) -> 513.88 | BJ4: =IFERROR(__xludf.DUMMYFUNCTION("""COMPUTED_VALUE"""),48.09) -> 48.09 | BK4: =IFERROR(__xludf.DUMMYFUNCTION("""COMPUTED_VALUE"""),11.14) -> 11.14 | BL4: =IFERROR(__xludf.DUMMYFUNCTION("""COMPUTED_VALUE"""),209.86) -> 209.86 | BM4: =IFERROR(__xludf.DUMMYFUNCTION("""COMPUTED_VALUE"""),105.35) -> 105.35
A5: 45427.667 | B5: =IFERROR(__xludf.DUMMYFUNCTION("""COMPUTED_VALUE"""),5308.15) -> 5308.15 | C5: =IFERROR(__xludf.DUMMYFUNCTION("""COMPUTED_VALUE"""),16742.39) -> 16742.39 | D5: =IFERROR(__xludf.DUMMYFUNCTION("""COMPUTED_VALUE"""),39908.0) -> 39908 | E5: =IFERROR(__xludf.DUMMYFUNCTION("""COMPUTED_VALUE"""),2109.46) -> 2109.46 | F5: =IFERROR(__xludf.DUMMYFUNCTION("""COMPUTED_VALUE"""),485.35) -> 485.35 | G5: =IFERROR(__xludf.DUMMYFUNCTION("""COMPUTED_VALUE"""),185.99) -> 185.99 | H5: =IFERROR(__xludf.DUMMYFUNCTION("""COMPUTED_VALUE"""),133.75) -> 133.75 | I5: =IFERROR(__xludf.DUMMYFUNCTION("""COMPUTED_VALUE"""),189.72) -> 189.72 | J5: =IFERROR(__xludf.DUMMYFUNCTION("""COMPUTED_VALUE"""),217.49) -> 217.49 | K5: =IFERROR(__xludf.DUMMYFUNCTION("""COMPUTED_VALUE"""),58.8) -> 58.8 | L5: =IFERROR(__xludf.DUMMYFUNCTION("""COMPUTED_VALUE"""),10.94) -> 10.94 | M5: =IFERROR(__xludf.DUMMYFUNCTION("""COMPUTED_VALUE"""),412.76) -> 412.76 | N5: =IFERROR(__xludf.DUMMYFUNCTION("""COMPUTED_VALUE"""),59.27) -> 59.27 | O5: =IFERROR(__xludf.DUMMYFUNCTION("""COMPUTED_VALUE"""),235.32) -> 235.32 | P5: =IFERROR(__xludf.DUMMYFUNCTION("""COMPUTED_VALUE"""),65.8) -> 65.8 | Q5: =IFERROR(__xludf.DUMMYFUNCTION("""COMPUTED_VALUE"""),360.04) -> 360.04 | R5: =IFERROR(__xludf.DUMMYFUNCTION("""COMPUTED_VALUE"""),49.97) -> 49.97 | S5: =IFERROR(__xludf.DUMMYFUNCTION("""COMPUTED_VALUE"""),149.0) -> 149 | T5: =IFERROR(__xludf.DUMMYFUNCTION("""COMPUTED_VALUE"""),163.05) -> 163.05 | U5: =IFERROR(__xludf.DUMMYFUNCTION("""COMPUTED_VALUE"""),343.28) -> 343.28 | V5: =IFERROR(__xludf.DUMMYFUNCTION("""COMPUTED_VALUE"""),36.84) -> 36.84 | W5: =IFERROR(__xludf.DUMMYFUNCTION("""COMPUTED_VALUE"""),63.13) -> 63.13 | X5: =IFERROR(__xludf.DUMMYFUNCTION("""COMPUTED_VALUE"""),96.91) -> 96.91 | Y5: =IFERROR(__xludf.DUMMYFUNCTION("""COMPUTED_VALUE"""),144.64) -> 144.64 | Z5: =IFERROR(__xludf.DUMMYFUNCTION("""COMPUTED_VALUE"""),118.8) -> 118.8 | AA5: =IFERROR(__xludf.DUMMYFUNCTION("""COMPUTED_VALUE"""),517.68) -> 517.68 | AB5: =IFERROR(__xludf.DUMMYFUNCTION("""COMPUTED_VALUE"""),52.42) -> 52.42 | AC5: =IFERROR(__xludf.DUMMYFUNCTION("""COMPUTED_VALUE"""),118.58) -> 118.58 | AD5: =IFERROR(__xludf.DUMMYFUNCTION("""COMPUTED_VALUE"""),259.32) -> 259.32 | AE5: =IFERROR(__xludf.DUMMYFUNCTION("""COMPUTED_VALUE"""),417.21) -> 417.21 | AF5: =IFERROR(__xludf.DUMMYFUNCTION("""COMPUTED_VALUE"""),294.59) -> 294.59 | AG5: =IFERROR(__xludf.DUMMYFUNCTION("""COMPUTED_VALUE"""),45.49) -> 45.49 | AH5: =IFERROR(__xludf.DUMMYFUNCTION("""COMPUTED_VALUE"""),67.01) -> 67.01 | AI5: =IFERROR(__xludf.DUMMYFUNCTION("""COMPUTED_VALUE"""),466.09) -> 466.09 | AJ5: =IFERROR(__xludf.DUMMYFUNCTION("""COMPUTED_VALUE"""),348.67) -> 348.67 | AK5: =IFERROR(__xludf.DUMMYFUNCTION("""COMPUTED_VALUE"""),86.6) -> 86.6 | AL5: =IFERROR(__xludf.DUMMYFUNCTION("""COMPUTED_VALUE"""),137.87) -> 137.87 | AM5: =IFERROR(__xludf.DUMMYFUNCTION("""COMPUTED_VALUE"""),399.39) -> 399.39 | AN5: =IFERROR(__xludf.DUMMYFUNCTION("""COMPUTED_VALUE"""),202.11) -> 202.11 | AO5: =IFERROR(__xludf.DUMMYFUNCTION("""COMPUTED_VALUE"""),464.08) -> 464.08 | AP5: =IFERROR(__xludf.DUMMYFUNCTION("""COMPUTED_VALUE"""),346.85) -> 346.85 | AQ5: =IFERROR(__xludf.DUMMYFUNCTION("""COMPUTED_VALUE"""),26.15) -> 26.15 | AR5: =IFERROR(__xludf.DUMMYFUNCTION("""COMPUTED_VALUE"""),84.72) -> 84.72 | AS5: =IFERROR(__xludf.DUMMYFUNCTION("""COMPUTED_VALUE"""),73.13) -> 73.13 | AT5: =IFERROR(__xludf.DUMMYFUNCTION("""COMPUTED_VALUE"""),423.08) -> 423.08 | AU5: =IFERROR(__xludf.DUMMYFUNCTION("""COMPUTED_VALUE"""),77.05) -> 77.05 | AV5: =IFERROR(__xludf.DUMMYFUNCTION("""COMPUTED_VALUE"""),94.63) -> 94.63 | AW5: =IFERROR(__xludf.DUMMYFUNCTION("""COMPUTED_VALUE"""),97.27) -> 97.27 | AX5: =IFERROR(__xludf.DUMMYFUNCTION("""COMPUTED_VALUE"""),36.42) -> 36.42 | AY5: =IFERROR(__xludf.DUMMYFUNCTION("""COMPUTED_VALUE"""),21.67) -> 21.67 | AZ5: =IFERROR(__xludf.DUMMYFUNCTION("""COMPUTED_VALUE"""),63.9) -> 63.9 | BA5: =IFERROR(__xludf.DUMMYFUNCTION("""COMPUTED_VALUE"""),28.82) -> 28.82 | BB5: =IFERROR(__xludf.DUMMYFUNCTION("""COMPUTED_VALUE"""),105.35) -> 105.35 | BC5: =IFERROR(__xludf.DUMMYFUNCTION("""COMPUTED_VALUE"""),162.68) -> 162.68 | BD5: =IFERROR(__xludf.DUMMYFUNCTION("""COMPUTED_VALUE"""),599.02) -> 599.02 | BE5: =IFERROR(__xludf.DUMMYFUNCTION("""COMPUTED_VALUE"""),219.55) -> 219.55 | BF5: =IFERROR(__xludf.DUMMYFUNCTION("""COMPUTED_VALUE"""),136.14) -> 136.14 | BG5: =IFERROR(__xludf.DUMMYFUNCTION("""COMPUTED_VALUE"""),6.8) -> 6.8 | BH5: =IFERROR(__xludf.DUMMYFUNCTION("""COMPUTED_VALUE"""),246.54) -> 246.54 | BI5: =IFERROR(__xludf.DUMMYFUNCTION("""COMPUTED_VALUE"""),517.55) -> 517.55 | BJ5: =IFERROR(__xludf.DUMMYFUNCTION("""COMPUTED_VALUE"""),48.16) -> 48.16 | BK5: =IFERROR(__xludf.DUMMYFUNCTION("""COMPUTED_VALUE"""),11.07) -> 11.07 | BL5: =IFERROR(__xludf.DUMMYFUNCTION("""COMPUTED_VALUE"""),209.0) -> 209 | BM5: =IFERROR(__xludf.DUMMYFUNCTION("""COMPUTED_VALUE"""),102.77) -> 102.77
